<?xml version="1.0"?>
<robot name="door">

  <link name="frame">
    <visual>
      <geometry>
        <cylinder length="0.6" radius="0.025"/>
      </geometry>
      <material name="gray"/>
    </visual>
    <collision>
      <geometry>
        <cylinder length="0.6" radius="0.025"/>
      </geometry>
    </collision>
    <inertial>
      <mass value="1"/>
      <inertia ixx="1" ixy="0.0" ixz="0.0" iyy="1" iyz="0.0" izz="1"/>
    </inertial>
  </link>

  <link name="door">
    <visual>
      <geometry>
        <box size="0.05 0.4 0.56"/>
      </geometry>
      <material name="white"/>
      <origin xyz="0 0.225 0.02"/>
    </visual>
    <collision>
      <geometry>
        <box size="0.05 0.4 0.56"/>
      </geometry>
      <origin xyz="0 0.225 0.02"/>
    </collision>
    <inertial>
      <mass value="0.1"/>
      <inertia ixx="0.001" ixy="0.0" ixz="0.0" iyy="0.001" iyz="0.0" izz="0.001"/>
    </inertial>
  </link>

  <link name="door_handle">
    <visual>
      <geometry>
        <box size="0.08 0.1 0.03"/>
      </geometry>
      <material name="red"/>
    </visual>
    <collision>
      <geometry>
        <box size="0.08 0.1 0.03"/>
      </geometry>
    </collision>
    <inertial>
      <mass value="0.1"/>
      <inertia ixx="0.001" ixy="0.0" ixz="0.0" iyy="0.001" iyz="0.0" izz="0.001"/>
    </inertial>
  </link>

  <joint name="hinge" type="revolute">
    <axis xyz="0 0 1"/>
    <limit effort="1000.0" lower="-1.5" upper="1.5" velocity="40"/>
    <parent link="frame"/>
    <child link="door"/>
    <dynamics damping="0.01" friction="0.01"/>
  </joint>

  <joint name="handle" type="fixed">
    <parent link="door"/>
    <child link="door_handle"/>
    <origin xyz="0.04 0.3 0"/>
  </joint>

  <material name="gray">
    <color rgba="0.5 0.5 0.5 1"/>
  </material>

  <material name="white">
    <color rgba="1 1 1 1"/>
  </material>

  <material name="red">
    <color rgba="1 0 0 1"/>
  </material>

</robot>